python: can't open file 'filename.py': [Errno 2] No such file or directory
Failed to load extension cogs.coding.
Traceback (most recent call last):
  File "/home/localadmin/Mercybot/bot.py", line 95, in __init__
    self.load_extension(extension)
  File "/home/localadmin/.local/lib/python3.9/site-packages/discord/ext/commands/bot.py", line 661, in load_extension
    raise errors.ExtensionNotFound(name)
discord.ext.commands.errors.ExtensionNotFound: Extension 'cogs.coding' could not be loaded.
In music play:
  File "/home/localadmin/.local/lib/python3.9/site-packages/discord/ext/commands/core.py", line 85, in wrapped
    ret = await coro(*args, **kwargs)
  File "/home/localadmin/Mercybot/cogs/music.py", line 477, in _play
    await ctx.invoke(self._join)
  File "/home/localadmin/.local/lib/python3.9/site-packages/discord/ext/commands/context.py", line 135, in invoke
    ret = await command.callback(*arguments, **kwargs)
  File "/home/localadmin/Mercybot/cogs/music.py", line 305, in _join
    ctx.voice_state.voice = await destination.connect()
  File "/home/localadmin/.local/lib/python3.9/site-packages/discord/abc.py", line 1150, in connect
    voice = cls(client, self)
  File "/home/localadmin/.local/lib/python3.9/site-packages/discord/voice_client.py", line 199, in __init__
    raise RuntimeError("PyNaCl library needed in order to use voice")
RuntimeError: PyNaCl library needed in order to use voice
In music play:
  File "/home/localadmin/.local/lib/python3.9/site-packages/discord/ext/commands/core.py", line 85, in wrapped
    ret = await coro(*args, **kwargs)
  File "/home/localadmin/Mercybot/cogs/music.py", line 477, in _play
    await ctx.invoke(self._join)
  File "/home/localadmin/.local/lib/python3.9/site-packages/discord/ext/commands/context.py", line 135, in invoke
    ret = await command.callback(*arguments, **kwargs)
  File "/home/localadmin/Mercybot/cogs/music.py", line 305, in _join
    ctx.voice_state.voice = await destination.connect()
  File "/home/localadmin/.local/lib/python3.9/site-packages/discord/abc.py", line 1150, in connect
    voice = cls(client, self)
  File "/home/localadmin/.local/lib/python3.9/site-packages/discord/voice_client.py", line 199, in __init__
    raise RuntimeError("PyNaCl library needed in order to use voice")
RuntimeError: PyNaCl library needed in order to use voice
In music play:
  File "/home/localadmin/.local/lib/python3.9/site-packages/discord/ext/commands/core.py", line 85, in wrapped
    ret = await coro(*args, **kwargs)
  File "/home/localadmin/Mercybot/cogs/music.py", line 477, in _play
    await ctx.invoke(self._join)
  File "/home/localadmin/.local/lib/python3.9/site-packages/discord/ext/commands/context.py", line 135, in invoke
    ret = await command.callback(*arguments, **kwargs)
  File "/home/localadmin/Mercybot/cogs/music.py", line 305, in _join
    ctx.voice_state.voice = await destination.connect()
  File "/home/localadmin/.local/lib/python3.9/site-packages/discord/abc.py", line 1150, in connect
    voice = cls(client, self)
  File "/home/localadmin/.local/lib/python3.9/site-packages/discord/voice_client.py", line 199, in __init__
    raise RuntimeError("PyNaCl library needed in order to use voice")
RuntimeError: PyNaCl library needed in order to use voice
Ready: Mercy#6887 (ID: 697087031859478630)
Shard ID 0 has resumed...
Shard ID 0 has resumed...
Shard ID 0 has resumed...
Shard ID 0 has resumed...
Shard ID 0 has resumed...
Shard ID 0 has resumed...
Shard ID 0 has resumed...
Shard ID 0 has resumed...
Shard ID 0 has resumed...
Shard ID 0 has resumed...
Shard ID 0 has resumed...
Shard ID 0 has resumed...
python: can't open file 'filename.py': [Errno 2] No such file or directory
Failed to load extension cogs.coding.
Traceback (most recent call last):
  File "/home/localadmin/Mercybot/bot.py", line 95, in __init__
    self.load_extension(extension)
  File "/home/localadmin/.local/lib/python3.9/site-packages/discord/ext/commands/bot.py", line 661, in load_extension
    raise errors.ExtensionNotFound(name)
discord.ext.commands.errors.ExtensionNotFound: Extension 'cogs.coding' could not be loaded.
Ready: Mercy#6887 (ID: 697087031859478630)
[tls @ 0x5589e4b500] Error in the pull function.
[tls @ 0x559e6ff500] Error in the pull function.
Traceback (most recent call last):
  File "/home/localadmin/.local/lib/python3.9/site-packages/discord/player.py", line 603, in run
    self._do_run()
  File "/home/localadmin/.local/lib/python3.9/site-packages/discord/player.py", line 590, in _do_run
    data = self.source.read()
  File "/home/localadmin/.local/lib/python3.9/site-packages/discord/player.py", line 543, in read
    ret = self.original.read()
  File "/home/localadmin/.local/lib/python3.9/site-packages/discord/player.py", line 228, in read
    ret = self._stdout.read(OpusEncoder.FRAME_SIZE)
AttributeError: 'NoneType' object has no attribute 'read'

During handling of the above exception, another exception occurred:

Traceback (most recent call last):
  File "/home/localadmin/.local/lib/python3.9/site-packages/discord/player.py", line 616, in _call_after
    self.after(error)
  File "/home/localadmin/Mercybot/cogs/music.py", line 244, in play_next_song
    raise VoiceError(str(error))
cogs.music.VoiceError: 'NoneType' object has no attribute 'read'
Shard ID 0 has resumed...
Shard ID 0 has resumed...
Shard ID 0 has resumed...
Shard ID 0 has resumed...
Shard ID 0 has resumed...
Shard ID 0 has resumed...
Shard ID 0 has resumed...
Shard ID 0 has resumed...
Shard ID 0 has resumed...
Shard ID 0 has resumed...
Shard ID 0 has resumed...
Shard ID 0 has resumed...
Shard ID 0 has resumed...
Shard ID 0 has resumed...
Shard ID 0 has resumed...
Shard ID 0 has resumed...
Shard ID 0 has resumed...
Shard ID 0 has resumed...
Shard ID 0 has resumed...
Shard ID 0 has resumed...
Shard ID 0 has resumed...
Shard ID 0 has resumed...
Shard ID 0 has resumed...
Shard ID 0 has resumed...
Shard ID 0 has resumed...
Shard ID 0 has resumed...
Shard ID 0 has resumed...
Shard ID 0 has resumed...
Shard ID 0 has resumed...
Shard ID 0 has resumed...
Shard ID 0 has resumed...
Shard ID 0 has resumed...
Shard ID 0 has resumed...
Shard ID 0 has resumed...
Shard ID 0 has resumed...
Shard ID 0 has resumed...
Shard ID 0 has resumed...
Shard ID 0 has resumed...
Shard ID 0 has resumed...
Shard ID 0 has resumed...
Shard ID 0 has resumed...
Shard ID 0 has resumed...
Shard ID 0 has resumed...
Shard ID 0 has resumed...
In bothealth:
  File "/home/localadmin/.local/lib/python3.9/site-packages/discord/ext/commands/core.py", line 85, in wrapped
    ret = await coro(*args, **kwargs)
  File "/home/localadmin/Mercybot/cogs/stats.py", line 706, in bothealth
    t for t in all_tasks
UnboundLocalError: local variable 'all_tasks' referenced before assignment
Ready: Mercy#6887 (ID: 697087031859478630)
Shard ID 0 has resumed...
Shard ID 0 has resumed...
Shard ID 0 has resumed...
Shard ID 0 has resumed...
Shard ID 0 has resumed...
Shard ID 0 has resumed...
Shard ID 0 has resumed...
Shard ID 0 has resumed...
Shard ID 0 has resumed...
Shard ID 0 has resumed...
Shard ID 0 has resumed...
Shard ID 0 has resumed...
Shard ID 0 has resumed...
Shard ID 0 has resumed...
Shard ID 0 has resumed...
Shard ID 0 has resumed...
Shard ID 0 has resumed...
Shard ID 0 has resumed...
Shard ID 0 has resumed...
Shard ID 0 has resumed...
Shard ID 0 has resumed...
Shard ID 0 has resumed...
Shard ID 0 has resumed...
Shard ID 0 has resumed...
Shard ID 0 has resumed...
Shard ID 0 has resumed...
Shard ID 0 has resumed...
Shard ID 0 has resumed...
Shard ID 0 has resumed...
Shard ID 0 has resumed...
Shard ID 0 has resumed...
Shard ID 0 has resumed...
Shard ID 0 has resumed...
Shard ID 0 has resumed...
Shard ID 0 has resumed...
Shard ID 0 has resumed...
Shard ID 0 has resumed...
Shard ID 0 has resumed...
Shard ID 0 has resumed...
Shard ID 0 has resumed...
Shard ID 0 has resumed...
Shard ID 0 has resumed...
Shard ID 0 has resumed...
Shard ID 0 has resumed...
Shard ID 0 has resumed...
Shard ID 0 has resumed...
Shard ID 0 has resumed...
Shard ID 0 has resumed...
Shard ID 0 has resumed...
Shard ID 0 has resumed...
Shard ID 0 has resumed...
Shard ID 0 has resumed...
Shard ID 0 has resumed...
Shard ID 0 has resumed...
Shard ID 0 has resumed...
Shard ID 0 has resumed...
Shard ID 0 has resumed...
Shard ID 0 has resumed...
Shard ID 0 has resumed...
Shard ID 0 has resumed...
Shard ID 0 has resumed...
Shard ID 0 has resumed...
Shard ID 0 has resumed...
Shard ID 0 has resumed...
Shard ID 0 has resumed...
Shard ID 0 has resumed...
Shard ID 0 has resumed...
Shard ID 0 has resumed...
Shard ID 0 has resumed...
Shard ID 0 has resumed...
Failed to load extension cogs.coding.
Traceback (most recent call last):
  File "/home/localadmin/Mercybot/bot.py", line 95, in __init__
    self.load_extension(extension)
  File "/home/localadmin/.local/lib/python3.9/site-packages/discord/ext/commands/bot.py", line 661, in load_extension
    raise errors.ExtensionNotFound(name)
discord.ext.commands.errors.ExtensionNotFound: Extension 'cogs.coding' could not be loaded.
Ready: Mercy#6887 (ID: 697087031859478630)
Shard ID 0 has resumed...
Shard ID 0 has resumed...
Shard ID 0 has resumed...
Shard ID 0 has resumed...
Shard ID 0 has resumed...
Shard ID 0 has resumed...
Shard ID 0 has resumed...
Shard ID 0 has resumed...
Shard ID 0 has resumed...
Shard ID 0 has resumed...
Shard ID 0 has resumed...
